<?xml version="1.0" encoding="UTF-8"?>
<!-- Generated by org.testng.reporters.JUnitReportReporter -->
<testsuite skipped="0" hostname="DESKTOP-P6FUNML" name="com.test.Exceptionhandling" tests="1" failures="0" timestamp="27 May 2020 11:08:30 GMT" time="0.026" errors="1">
  <testcase name="add" time="0.026" classname="com.test.Exceptionhandling">
    <error type="org.testng.TestException" message="
Expected exception of type class java.lang.NumberFormatException but got org.testng.internal.thread.ThreadTimeoutException: Method com.test.Exceptionhandling.add() didn&#039;t finish within the time-out 2">
      <![CDATA[org.testng.TestException: 
Expected exception of type class java.lang.NumberFormatException but got org.testng.internal.thread.ThreadTimeoutException: Method com.test.Exceptionhandling.add() didn't finish within the time-out 2
at org.testng.internal.ExpectedExceptionsHolder.wrongException(ExpectedExceptionsHolder.java:68)
at org.testng.internal.Invoker.considerExceptions(Invoker.java:1130)
at org.testng.internal.Invoker.invokeMethod(Invoker.java:615)
at org.testng.internal.Invoker.invokeTestMethod(Invoker.java:719)
at org.testng.internal.Invoker.invokeTestMethods(Invoker.java:989)
at org.testng.internal.TestMethodWorker.invokeTestMethods(TestMethodWorker.java:125)
at org.testng.internal.TestMethodWorker.run(TestMethodWorker.java:109)
at org.testng.TestRunner.privateRun(TestRunner.java:648)
at org.testng.TestRunner.run(TestRunner.java:505)
at org.testng.SuiteRunner.runTest(SuiteRunner.java:455)
at org.testng.SuiteRunner.runSequentially(SuiteRunner.java:450)
at org.testng.SuiteRunner.privateRun(SuiteRunner.java:415)
at org.testng.SuiteRunner.run(SuiteRunner.java:364)
at org.testng.SuiteRunnerWorker.runSuite(SuiteRunnerWorker.java:52)
at org.testng.SuiteRunnerWorker.run(SuiteRunnerWorker.java:84)
at org.testng.TestNG.runSuitesSequentially(TestNG.java:1208)
at org.testng.TestNG.runSuitesLocally(TestNG.java:1137)
at org.testng.TestNG.runSuites(TestNG.java:1049)
at org.testng.TestNG.run(TestNG.java:1017)
at org.testng.remote.AbstractRemoteTestNG.run(AbstractRemoteTestNG.java:115)
at org.testng.remote.RemoteTestNG.initAndRun(RemoteTestNG.java:251)
at org.testng.remote.RemoteTestNG.main(RemoteTestNG.java:77)
Caused by: org.testng.internal.thread.ThreadTimeoutException: Method com.test.Exceptionhandling.add() didn't finish within the time-out 2
at java.io.FileOutputStream.writeBytes(Native Method)
at java.io.FileOutputStream.write(Unknown Source)
at java.io.BufferedOutputStream.flushBuffer(Unknown Source)
at java.io.BufferedOutputStream.flush(Unknown Source)
at java.io.PrintStream.write(Unknown Source)
at sun.nio.cs.StreamEncoder.writeBytes(Unknown Source)
at sun.nio.cs.StreamEncoder.implFlushBuffer(Unknown Source)
at sun.nio.cs.StreamEncoder.flushBuffer(Unknown Source)
at java.io.OutputStreamWriter.flushBuffer(Unknown Source)
at java.io.PrintStream.newLine(Unknown Source)
at java.io.PrintStream.println(Unknown Source)
at com.test.Exceptionhandling.add(Exceptionhandling.java:13)
at sun.reflect.NativeMethodAccessorImpl.invoke0(Native Method)
at sun.reflect.NativeMethodAccessorImpl.invoke(Unknown Source)
at sun.reflect.DelegatingMethodAccessorImpl.invoke(Unknown Source)
at java.lang.reflect.Method.invoke(Unknown Source)
at org.testng.internal.MethodInvocationHelper.invokeMethod(MethodInvocationHelper.java:124)
at org.testng.internal.InvokeMethodRunnable.runOne(InvokeMethodRunnable.java:54)
at org.testng.internal.InvokeMethodRunnable.run(InvokeMethodRunnable.java:40)
at java.util.concurrent.Executors$RunnableAdapter.call(Unknown Source)
at java.util.concurrent.FutureTask.run(Unknown Source)
at java.util.concurrent.ThreadPoolExecutor.runWorker(Unknown Source)
at java.util.concurrent.ThreadPoolExecutor$Worker.run(Unknown Source)
at java.lang.Thread.run(Unknown Source)
]]>
    </error>
  </testcase> <!-- add -->
</testsuite> <!-- com.test.Exceptionhandling -->
